<?xml version="1.0"?>
<!-- based on https://github.com/ROBOTIS-GIT/open_manipulator -->
<robot xmlns:xacro="http://www.ros.org/wiki/xacro">

  <xacro:macro name="open_manipulator_x"
    params="parent_link xyz rpy
            tf_prefix:=None
            use_sim collision_enabled:=true
            usb_port:=/dev/ttyUSB0
            baud_rate:=115200
            joint1_limit_min:=-2.356
            joint1_limit_max:=5.934
            control_period:=0.1
            manipulator_joint_profile_acceleration:=200
            manipulator_joint_profile_velocity:=500
            gripper_joint_profile_acceleration:=500
            gripper_joint_profile_velocity:=1000">

    <!-- collision_enabled parameter added due to collisions using visual meshes, which are very
    heavy and slow down simulation, this parameter allows to easily disable them -->

    <xacro:if value="${tf_prefix == 'None'}">
      <xacro:property name="tf_prefix_ext" value="" />
    </xacro:if>
    <xacro:unless value="${tf_prefix == 'None'}">
      <xacro:property name="tf_prefix_ext" value="${tf_prefix}_" />
    </xacro:unless>

    <material name="grey">
      <color rgba="0.05 0.05 0.05 1.0" />
    </material>

    <xacro:property name="effort_limit" value="1" />
    <xacro:property name="velocity_limit" value="4.8" />
    <xacro:property name="damping" value="0.1" />

    <joint name="${parent_link}_to_${tf_prefix_ext}link1" type="fixed">
      <origin xyz="${xyz}" rpy="${rpy}" />
      <parent link="${parent_link}" />
      <child link="${tf_prefix_ext}link1" />
    </joint>

    <link name="${tf_prefix_ext}link1">
      <visual>
        <origin xyz="0.0 0.0 0.0" rpy="0.0 0.0 0.0" />
        <geometry>
          <mesh filename="file://$(find open_manipulator_x_description)/meshes/link1.stl"
            scale="0.001 0.001 0.001" />
        </geometry>
        <material name="grey" />
      </visual>

      <xacro:if value="${collision_enabled}">
        <collision>
          <origin xyz="0.0 0.0 0.0" rpy="0.0 0.0 0.0" />
          <geometry>
            <mesh filename="file://$(find open_manipulator_x_description)/meshes/link1.stl"
              scale="0.001 0.001 0.001" />
          </geometry>
        </collision>
      </xacro:if>

      <inertial>
        <origin xyz="3.0876154e-04 0.0000000e+00 -1.2176461e-04" />
        <mass value="7.9119962e-02" />
        <inertia ixx="1.2505234e-05" ixy="0.0"           ixz="-1.7855208e-07"
                                     iyy="2.1898364e-05" iyz="0.0"
                                                         izz="1.9267361e-05" />
      </inertial>
    </link>

    <joint name="${tf_prefix_ext}joint1" type="revolute">
      <parent link="${tf_prefix_ext}link1" />
      <child link="${tf_prefix_ext}link2" />
      <origin xyz="0.012 0.0 0.017" rpy="0.0 0.0 0.0" />
      <axis xyz="0 0 1" />
      <!-- Joint1 motion is limited only by length of the cable -->
      <limit velocity="${velocity_limit}" effort="${effort_limit}" lower="${joint1_limit_min}"
        upper="${joint1_limit_max}" />
      <dynamics damping="${damping}" />
    </joint>

    <link name="${tf_prefix_ext}link2">
      <visual>
        <origin xyz="0.0 0.0 0.019" rpy="0.0 0.0 0.0" />
        <geometry>
          <mesh filename="file://$(find open_manipulator_x_description)/meshes/link2.stl"
            scale="0.001 0.001 0.001" />
        </geometry>
        <material name="grey" />
      </visual>

      <xacro:if value="${collision_enabled}">
        <collision>
          <origin xyz="0.0 0.0 0.019" rpy="0.0 0.0 0.0" />
          <geometry>
            <mesh
              filename="file://$(find open_manipulator_x_description)/meshes/link2.stl"
              scale="0.001 0.001 0.001" />
          </geometry>
        </collision>
      </xacro:if>

      <inertial>
        <origin xyz="-3.0184870e-04 5.4043684e-04 ${0.018 + 2.9433464e-02}" />
        <mass value="9.8406837e-02" />
        <inertia ixx="3.4543422e-05" ixy="-1.6031095e-08" ixz="-3.8375155e-07"
                                     iyy="3.2689329e-05"  iyz="2.8511935e-08"
                                                          izz="1.8850320e-05" />
      </inertial>
    </link>

    <joint name="${tf_prefix_ext}joint2" type="revolute">
      <parent link="${tf_prefix_ext}link2" />
      <child link="${tf_prefix_ext}link3" />
      <origin xyz="0.0 0.0 0.0595" rpy="0.0 0.0 0.0" />
      <axis xyz="0 1 0" />
      <limit velocity="${velocity_limit}" effort="${effort_limit}" lower="${-pi*0.57}"
        upper="${pi*0.5}" />
      <dynamics damping="${damping}" />
    </joint>

    <link name="${tf_prefix_ext}link3">
      <visual>
        <origin xyz="0.0 0.0 0.0" rpy="0.0 0.0 0.0" />
        <geometry>
          <mesh filename="file://$(find open_manipulator_x_description)/meshes/link3.stl"
            scale="0.001 0.001 0.001" />
        </geometry>
        <material name="grey" />
      </visual>

      <xacro:if value="${collision_enabled}">
        <collision>
          <origin xyz="0.0 0.0 0.0" rpy="0.0 0.0 0.0" />
          <geometry>
            <mesh
              filename="file://$(find open_manipulator_x_description)/meshes/link3.stl"
              scale="0.001 0.001 0.001" />
          </geometry>
        </collision>
      </xacro:if>

      <inertial>
        <origin xyz="1.0308393e-02 3.7743363e-04 1.0170197e-01" />
        <mass value="1.3850917e-01" />
        <inertia ixx="3.3055381e-04" ixy="-9.7940978e-08" ixz="-3.8505711e-05"
                                     iyy="3.4290447e-04"  iyz="-1.5717516e-06"
                                                          izz="6.0346498e-05" />
      </inertial>
    </link>

    <joint name="${tf_prefix_ext}joint3" type="revolute">
      <parent link="${tf_prefix_ext}link3" />
      <child link="${tf_prefix_ext}link4" />
      <origin xyz="0.024 0.0 0.128" rpy="0.0 0.0 0.0" />
      <axis xyz="0 1 0" />
      <limit velocity="${velocity_limit}" effort="${effort_limit}" lower="${-pi*0.5}"
        upper="${pi*0.44}" />
      <dynamics damping="${damping}" />
    </joint>

    <link name="${tf_prefix_ext}link4">
      <visual>
        <origin xyz="0.0 0.0 0.0" rpy="0.0 0.0 0.0" />
        <geometry>
          <mesh filename="file://$(find open_manipulator_x_description)/meshes/link4.stl"
            scale="0.001 0.001 0.001" />
        </geometry>
        <material name="grey" />
      </visual>

      <xacro:if value="${collision_enabled}">
        <collision>
          <origin xyz="0.0 0.0 0.0" rpy="0.0 0.0 0.0" />
          <geometry>
            <mesh
              filename="file://$(find open_manipulator_x_description)/meshes/link4.stl"
              scale="0.001 0.001 0.001" />
          </geometry>
        </collision>
      </xacro:if>

      <inertial>
        <origin xyz="9.0909590e-02 3.8929816e-04 2.2413279e-04" />
        <mass value="1.3274562e-01" />
        <inertia ixx="3.0654178e-05" ixy="-1.2764155e-06" ixz="-2.6874417e-07"
                                     iyy="2.4230292e-04"  iyz="1.1559550e-08"
                                                          izz="2.5155057e-04" />
      </inertial>
    </link>

    <joint name="${tf_prefix_ext}joint4" type="revolute">
      <parent link="${tf_prefix_ext}link4" />
      <child link="${tf_prefix_ext}link5" />
      <origin xyz="0.124 0.0 0.0" rpy="0.0 0.0 0.0" />
      <axis xyz="0 1 0" />
      <limit velocity="${velocity_limit}" effort="${effort_limit}" lower="${-pi*0.55}"
        upper="${pi*0.65}" />
      <dynamics damping="${damping}" />
    </joint>

    <link name="${tf_prefix_ext}link5">
      <visual>
        <origin xyz="0.0 0.0 0.0" rpy="0.0 0.0 0.0" />
        <geometry>
          <mesh filename="file://$(find open_manipulator_x_description)/meshes/link5.stl"
            scale="0.001 0.001 0.001" />
        </geometry>
        <material name="grey" />
      </visual>

      <xacro:if value="${collision_enabled}">
        <collision>
          <origin xyz="0.0 0.0 0.0" rpy="0.0 0.0 0.0" />
          <geometry>
            <mesh
              filename="file://$(find open_manipulator_x_description)/meshes/link5.stl"
              scale="0.001 0.001 0.001" />
          </geometry>
        </collision>
      </xacro:if>

      <inertial>
        <origin xyz="4.4206755e-02 3.6839985e-07 8.9142216e-03" />
        <mass value="1.4327573e-01" />
        <inertia ixx="8.0870749e-05" ixy="0.0"           ixz="-1.0157896e-06"
                                     iyy="7.5980465e-05" iyz="0.0"
                                                         izz="9.3127351e-05" />
      </inertial>
    </link>

    <joint name="${tf_prefix_ext}gripper_left_joint" type="prismatic">
      <parent link="${tf_prefix_ext}link5" />
      <child link="${tf_prefix_ext}gripper_left_link" />
      <origin xyz="0.0817 0.021 0.0" rpy="0.0 0.0 0.0" />
      <axis xyz="0 1 0" />
      <limit velocity="${velocity_limit}" effort="${effort_limit}" lower="-0.010" upper="0.019" />
      <dynamics damping="${damping}" />
    </joint>

    <link name="${tf_prefix_ext}gripper_left_link">
      <visual>
        <origin xyz="0.0 0.0 0.0" rpy="0.0 0.0 0.0" />
        <geometry>
          <mesh
            filename="file://$(find open_manipulator_x_description)/meshes/gripper_left_palm.stl"
            scale="0.001 0.001 0.001" />
        </geometry>
        <material name="grey" />
      </visual>

      <xacro:if value="${collision_enabled}">
        <collision>
          <origin xyz="0.0 0.0 0.0" rpy="0.0 0.0 0.0" />
          <geometry>
            <mesh
              filename="file://$(find open_manipulator_x_description)/meshes/gripper_left_palm.stl"
              scale="0.001 0.001 0.001" />
          </geometry>
        </collision>
      </xacro:if>

      <inertial>
        <origin xyz="0.0 0.0 0.0" />
        <mass value="1.0e-03" />
        <inertia ixx="1.0e-06" ixy="0.0"     ixz="0.0"
                               iyy="1.0e-06" iyz="0.0"
                                             izz="1.0e-06" />
      </inertial>
    </link>

    <joint name="${tf_prefix_ext}gripper_right_joint" type="prismatic">
      <parent link="${tf_prefix_ext}link5" />
      <child link="${tf_prefix_ext}gripper_right_link" />
      <origin xyz="0.0817 -0.021 0.0" rpy="0.0 0.0 0.0" />
      <axis xyz="0 -1 0" />
      <limit velocity="${velocity_limit}" effort="${effort_limit}" lower="-0.010" upper="0.019" />
      <mimic joint="${tf_prefix_ext}gripper_left_joint" multiplier="1" />
      <dynamics damping="${damping}" />
    </joint>

    <link name="${tf_prefix_ext}gripper_right_link">
      <visual>
        <origin xyz="0.0 0.0 0.0" rpy="0.0 0.0 0.0" />
        <geometry>
          <mesh
            filename="file://$(find open_manipulator_x_description)/meshes/gripper_right_palm.stl"
            scale="0.001 0.001 0.001" />
        </geometry>
        <material name="grey" />
      </visual>

      <xacro:if value="${collision_enabled}">
        <collision>
          <origin xyz="0.0 0.0 0.0" rpy="0.0 0.0 0.0" />
          <geometry>
            <mesh
              filename="file://$(find open_manipulator_x_description)/meshes/gripper_right_palm.stl"
              scale="0.001 0.001 0.001" />
          </geometry>
        </collision>
      </xacro:if>

      <inertial>
        <origin xyz="0 0 0" />
        <mass value="1.0e-03" />
        <inertia ixx="1.0e-06" ixy="0.0"     ixz="0.0"
                               iyy="1.0e-06" iyz="0.0"
                                             izz="1.0e-06" />
      </inertial>
    </link>

    <joint name="${tf_prefix_ext}end_effector_joint" type="fixed">
      <parent link="${tf_prefix_ext}link5" />
      <child link="${tf_prefix_ext}end_effector_link" />
      <origin xyz="0.126 0.0 0.0" rpy="0.0 0.0 0.0" />
    </joint>

    <link name="${tf_prefix_ext}end_effector_link" />

    <ros2_control name="manipulator" type="system">

      <xacro:if value="$(arg use_sim)">
        <hardware>
          <plugin>ign_ros2_control/IgnitionSystem</plugin>
        </hardware>
      </xacro:if>

      <xacro:unless value="$(arg use_sim)">
        <hardware>
          <plugin>open_manipulator_x_hardware/OpenManipulatorXSystem</plugin>
          <param name="usb_port">${usb_port}</param>
          <param name="baud_rate">${baud_rate}</param>
          <param name="control_period">${control_period}</param>
          <param name="manipulator_joint_profile_acceleration">${manipulator_joint_profile_acceleration}</param>
          <param name="manipulator_joint_profile_velocity">${manipulator_joint_profile_velocity}</param>
          <param name="gripper_joint_profile_acceleration">${gripper_joint_profile_acceleration}</param>
          <param name="gripper_joint_profile_velocity">${gripper_joint_profile_velocity}</param>
        </hardware>
      </xacro:unless>

      <joint name="${tf_prefix_ext}joint1">
        <command_interface name="position">
          <param name="min">${joint1_limit_min}</param>
          <param name="max">${joint1_limit_max}</param>
        </command_interface>
        <state_interface name="position" />
        <state_interface name="velocity" />
      </joint>
      <joint name="${tf_prefix_ext}joint2">
        <command_interface name="position">
          <param name="min">${-pi*0.57}</param>
          <param name="max">${pi*0.5}</param>
        </command_interface>
        <state_interface name="position" />
        <state_interface name="velocity" />
      </joint>
      <joint name="${tf_prefix_ext}joint3">
        <command_interface name="position">
          <param name="min">${-pi*0.3}</param>
          <param name="max">${pi*0.44}</param>
        </command_interface>
        <state_interface name="position" />
        <state_interface name="velocity" />
      </joint>
      <joint name="${tf_prefix_ext}joint4">
        <command_interface name="position">
          <param name="min">${-pi*0.57}</param>
          <param name="max">${pi*0.65}</param>
        </command_interface>
        <state_interface name="position" />
        <state_interface name="velocity" />
      </joint>
      <joint name="${tf_prefix_ext}gripper_left_joint">
        <command_interface name="position">
          <param name="min">-0.010</param>
          <param name="max">0.019</param>
        </command_interface>
        <state_interface name="position" />
        <state_interface name="velocity" />
      </joint>

    </ros2_control>

  </xacro:macro>

</robot>